Workbook

Sheet Lists & Settings
A1: Position Status | B1: Recruitment Stage | C1: Interview Status | D1: Client Status | E1: Decision | F1: Priority | G1: Yes / No | H1: Ref Numbers | J1: Must-Have Fit | K1: Definition | M1: Must-Have Fit | N1: Min ATS Match | O1: Calculated Decision | Q1: Decision Rules | S1: Talent Pool Status | T1: Seniority Level | U1: Filled Source
A2: Active | B2: Applied | C2: Not Scheduled | D2: Not Submitted | E2: Priority Shortlist | F2: High | G2: Yes | H2: 001 | J2: Pass | K2: All knockout / mandatory requirements are clearly evidenced. | M2: Pass | N2: 0.75 | O2: Priority Shortlist | Q2: Must-Have Fail overrides ATS Match and results in Reject. | S2: Active | T2: Individual Contributor | U2: Osynix Recruiter
A3: On Hold | B3: HR Screening | C3: Scheduled | D3: Submitted | E3: Shortlist | F3: Medium | G3: No | J3: Partial | K3: Core must-have fit is plausible, but at least one knockout requirement needs validation; no confirmed hard failure. | M3: Pass | N3: 0.6 | O3: Shortlist | Q3: ATS thresholds apply only after the Must-Have gate. | S3: Priority Talent | T3: Senior Professional | U3: Client Direct Hire
A4: Closed | B4: Background Check | C4: Completed | D4: Under Review | E4: Hold | F4: Low | J4: Fail | K4: One or more knockout / mandatory requirements are clearly not met. | M4: Pass | N4: 0 | O4: Hold | Q4: Partial can Shortlist / Hold / Reject, but cannot Priority Shortlist. | S4: Passive | T4: Team Lead / Supervisor | U4: Other
B5: Consider
A6: Filled | B6: Shortlisted | C6: No Show | D6: Client Shortlisted | E6: Reject | J6: Insufficient Evidence | K6: The CV / ATS record does not provide enough evidence to determine must-have fit. | M6: Partial | N6: 0.7 | O6: Shortlist | Q6: Insufficient Evidence never auto-shortlists. | S6: Placed | T6: Manager
A7: Cancelled | B7: Technical Interview | C7: Reschedule Required | D7: Client Rejected | E7: Insufficient Evidence | M7: Partial | N7: 0.55 | O7: Hold | Q7: Recruitment Stage is an operational status; it is synchronized at screening but remains manually moveable afterward. | S7: Archived | T7: Senior Manager
B8: Final Interview | C8: Not Required | D8: Client Interview | M8: Partial | N8: 0 | O8: Reject | S8: Do Not Contact | T8: Head / Director
B9: Client Interview | D9: Offer | M9: Fail | N9: 0 | O9: Reject | T9: Executive / GM
B10: Offer Sent | D10: Hired | M10: Insufficient Evidence | N10: 0 | O10: Insufficient Evidence | T10: Founder / Owner
B11: Hired | T11: Officer / Command
B12: Hold
B13: Rejected

Sheet Positions Master
A1: Ref # | B1: Client | C1: Position | D1: Location | E1: Open Date | F1: Status | G1: Priority | H1: Hiring Target | I1: Profiles Screened | J1: Shortlisted | K1: Client Interviews | L1: Offers | M1: Hired | N1: Average ATS Match | O1: Hiring Manager / Contact | P1: JD / File Link | Q1: Notes | R1: Last Updated | S1: JD File Hash | T1: Assigned Recruiter | U1: Created By | V1: Created Date | W1: Position Closed By | X1: Position Closed Date | Y1: Closure Status | Z1: Last Updated By | AA1: Filled Source | AB1: Hired Candidate ID | AC1: Hired Candidate Name | AD1: Closure Reason
A2: 001 | B2: Nobel Business Solutions | C2: Operations Manager / General Manager (LIMO & Chauffeur Services) | D2: Lahore | E2: 46290 | F2: Active | G2: High | H2: 1 | I2: =COUNTIF(Candidates!$B$2:$B$2000,A2) -> 30 | J2: =COUNTIFS(Candidates!$B$2:$B$2000,A2,Candidates!$S$2:$S$2000,"Priority Shortlist")+COUNTIFS(Candidates!$B$2:$B$2000,A2,Candidates!$S$2:$S$2000,"Shortlist") -> 4 | K2: =COUNTIFS(Candidates!$B$2:$B$2000,A2,Candidates!$T$2:$T$2000,"Client Interview") -> 0 | L2: =COUNTIFS(Candidates!$B$2:$B$2000,A2,Candidates!$T$2:$T$2000,"Offer Sent") -> 0 | M2: =COUNTIFS(Candidates!$B$2:$B$2000,A2,Candidates!$T$2:$T$2000,"Hired") -> 0 | N2: =IFERROR(AVERAGEIF(Candidates!$B$2:$B$2000,A2,Candidates!$M$2:$M$2000),0) -> 0.392 | Q2: Direct LIMO/chauffeur service management and US-customer exposure are high-weight requirements. | R2: 46293.146 | W2: Tauqeer Zahid | X2: 46293 | Y2: Filled | Z2: Tauqeer Zahid
A3: 002 | B3: Baba Bakers | C3: Production Manager (Factory) | D3: Gujranwala | E3: 46292 | F3: Active | G3: High | H3: 1 | I3: 0 | J3: 0 | K3: 0 | L3: 0 | M3: 0 | R3: 46291.564
A4: 003 | B4: Baba Bakers | C4: Export Manager | D4: Lahore | E4: 46292 | F4: Filled | G4: Medium | H4: 1 | I4: 0 | J4: 0 | K4: 0 | L4: 0 | M4: 0 | P4: Export Manager.docx | R4: 46292.186 | S4: d43bc043002d670e98a0106f82a1dc472352261b73bd4103d12d0b2b529a9be0
A5: 004 | B5: Baba Bakers | C5: Procurement Executive (Factory) | D5: Lahore | E5: 46293 | F5: Active | G5: Medium | H5: 1 | I5: 0 | J5: 0 | K5: 0 | L5: 0 | M5: 0 | P5: https://docs.google.com/document/d/1ajXMUauVPWAzTwo9Bg6GJGxwT_KhfKet/edit?usp=drivesdk&ouid=100269677063860344655&rtpof=true&sd=true | R5: 46293.25 | S5: 1dbac5440e423cfeb1b7a95799785e99a4e9c28853b89d9d34c6139cbe6e40df | W5: Tauqeer Zahid | X5: 46293 | Y5: Filled | Z5: Tauqeer Zahid
A6: 005 | B6: HR Ways | C6: B2B Sales Executive – US IT Staffing | D6: Karachi | E6: 46295 | F6: Active | G6: High | H6: 1 | I6: 0 | J6: 0 | K6: 0 | L6: 0 | M6: 0 | P6: https://drive.google.com/file/d/1el2PZ9t_qn36A1jZtAIPx43xNmnkYhai/view?usp=drivesdk | R6: 46295.182 | S6: 0eff71ba095c0c1c18b3e5cee51cd37db5c01751de7724965881f7e5399724aa

Sheet Candidates
A1: Candidate ID | B1: Ref # | C1: Candidate Name | D1: Mobile / Phone Number | E1: Email ID | F1: Current Designation | G1: Current Company | H1: Location | I1: Total Experience (Yrs) | J1: Relevant Industry Experience (Yrs) | K1: Date Screened | L1: Evidence Strength /10 | M1: ATS Match % | N1: Must-Have Fit | O1: Core Role Fit /10 | P1: Key Strengths | Q1: Key Gap / Risk | R1: Executive Assessment | S1: Decision | T1: Recruitment Stage | U1: Interview Status | V1: Client Status | W1: Expected Salary | X1: Availability | Y1: Recruiter Notes | Z1: CV / File Link | AA1: Last Updated | AB1: Criterion Results JSON
A2: CAND-001 | B2: 001 | C2: Zain Abid | D2: +92 328 4582394 | E2: zain199819@gmail.com | F2: Freelance UX/UI Designer / Frontend | G2: Freelancer | H2: Lahore Cantt | K2: 46290 | L2: 6 | M2: 0.15 | N2: Fail | O2: 4 | P2: Creative/technical background with some project-management and leadership exposure. | Q2: No meaningful senior transport operations, LIMO/chauffeur management, US customer operations, dispatch, affiliate/farm-out, or limo systems experience. | R2: Profile does not meet Ref #001 core industry requirements despite some transferable project/marketing exposure. | S2: =IF($C2="","",IF(OR($M2="",$N2=""),'Lists & Settings'!$O$10,IF($N2="Fail",'Lists & Settings'!$O$9,IF($N2="Insufficient Evidence",'Lists & Settings'!$O$10,IF($N2="Pass",IF($M2>='Lists & Settings'!$N$2,'Lists & Settings'!$O$2,IF($M2>='Lists & Settings'!$N$3,'Lists & Settings'!$O$3,'Lists & Settings'!$O$4)),IF($N2="Partial",IF($M2>='Lists & Settings'!$N$6,'Lists & Settings'!$O$6,IF($M2>='Lists & Settings'!$N$7,'Lists & Settings'!$O$7,'Lists & Settings'!$O$8)),'Lists & Settings'!$O$10)))))) -> Reject | T2: Rejected | Y2: Qualitative Must-Have Fit: Fail. Latest recalibrated score under strict LIMO/chauffeur + US-market benchmark. | AA2: 46291
A3: CAND-002 | B3: 001 | C3: Sidra Azam | D3: +92 304 4889746 | E3: sidrafatima03044@gmail.com | F3: Senior Sales Executive | G3: Cresset Technologies | H3: Lahore | I3: 6 | K3: 46290 | L3: 7 | M3: 0.24 | N3: Fail | O3: 7 | P3: 6+ years in sales/revenue growth, client acquisition, team leadership and multi-account operations. | Q3: No chauffeur/limo/ground-transportation operations, dispatch, affiliate/farm-out, US limo service, or limo-platform experience. | R3: Strong commercial profile but materially outside the required LIMO/chauffeur operations domain. | S3: =IF($C3="","",IF(OR($M3="",$N3=""),'Lists & Settings'!$O$10,IF($N3="Fail",'Lists & Settings'!$O$9,IF($N3="Insufficient Evidence",'Lists & Settings'!$O$10,IF($N3="Pass",IF($M3>='Lists & Settings'!$N$2,'Lists & Settings'!$O$2,IF($M3>='Lists & Settings'!$N$3,'Lists & Settings'!$O$3,'Lists & Settings'!$O$4)),IF($N3="Partial",IF($M3>='Lists & Settings'!$N$6,'Lists & Settings'!$O$6,IF($M3>='Lists & Settings'!$N$7,'Lists & Settings'!$O$7,'Lists & Settings'!$O$8)),'Lists & Settings'!$O$10)))))) -> Reject | T3: Rejected | Y3: Qualitative Must-Have Fit: Fail. Latest recalibrated score under strict Ref #001 benchmark. | AA3: 46291
A4: CAND-003 | B4: 001 | C4: Ejaz Mehmood | D4: +92 308 4196749 | E4: emahmood91@gmail.com | F4: Limousine Dispatcher & Operations Manager (Remote) | G4: Abiel Limo Worldwide | H4: Lahore | I4: 8 | J4: 8 | K4: 46290 | L4: 9.5 | M4: 0.89 | N4: Pass | O4: 7.5 | P4: 8+ years direct limousine/chauffeur operations; dispatch, reservations, driver assignment, affiliate coordination, Limo Anywhere; USA/UK/Canada bookings. | Q4: CV does not fully evidence broad GM-level ownership across marketing, SEO, development teams and full P&L. | R4: Best direct domain match: proven limo/chauffeur dispatch and explicit US-market booking exposure. Broader GM scope should be validated in interview. | S4: =IF($C4="","",IF(OR($M4="",$N4=""),'Lists & Settings'!$O$10,IF($N4="Fail",'Lists & Settings'!$O$9,IF($N4="Insufficient Evidence",'Lists & Settings'!$O$10,IF($N4="Pass",IF($M4>='Lists & Settings'!$N$2,'Lists & Settings'!$O$2,IF($M4>='Lists & Settings'!$N$3,'Lists & Settings'!$O$3,'Lists & Settings'!$O$4)),IF($N4="Partial",IF($M4>='Lists & Settings'!$N$6,'Lists & Settings'!$O$6,IF($M4>='Lists & Settings'!$N$7,'Lists & Settings'!$O$7,'Lists & Settings'!$O$8)),'Lists & Settings'!$O$10)))))) -> Priority Shortlist | T4: Final Interview | U4: Completed | V4: Client Rejected | Y4: Qualitative Must-Have Fit: Partial / Strong. Explicit US limo/chauffeur exposure. Priority candidate. | AA4: 46291
A5: CAND-004 | B5: 001 | C5: Mansoor Ahmed Bajwa | D5: 0343-7709958 | E5: mansoorbajwa80@gmail.com | F5: Manager Administration Transport | G5: BIGWAY PVT LTD | H5: Lahore | I5: 26 | J5: 8 | K5: 46290 | L5: 8.5 | M5: 0.43 | N5: Fail | O5: 8.5 | P5: Senior transport/fleet leadership, route planning, driver supervision, budgets, logistics, large-team management and operational control. | Q5: No demonstrated LIMO/chauffeur service model, US customers, chauffeur reservations, affiliate/farm-out operations, or limo booking platforms. | R5: Strong transportation leader but direct client-required limo/chauffeur and US-market experience is missing. | S5: =IF($C5="","",IF(OR($M5="",$N5=""),'Lists & Settings'!$O$10,IF($N5="Fail",'Lists & Settings'!$O$9,IF($N5="Insufficient Evidence",'Lists & Settings'!$O$10,IF($N5="Pass",IF($M5>='Lists & Settings'!$N$2,'Lists & Settings'!$O$2,IF($M5>='Lists & Settings'!$N$3,'Lists & Settings'!$O$3,'Lists & Settings'!$O$4)),IF($N5="Partial",IF($M5>='Lists & Settings'!$N$6,'Lists & Settings'!$O$6,IF($M5>='Lists & Settings'!$N$7,'Lists & Settings'!$O$7,'Lists & Settings'!$O$8)),'Lists & Settings'!$O$10)))))) -> Reject | T5: Rejected | Y5: Original assessment: Hold / Backup. Qualitative Must-Have Fit: Fail on direct LIMO/US requirement. | AA5: 46291
A6: CAND-005 | B6: 001 | C6: Fakhra Sikander | D6: +92 322 4720240 | E6: fakhramunir@hotmail.com | F6: Call Center Manager | G6: 3D Lifestyle | H6: Johar Town, Lahore | K6: 46290 | L6: 7.5 | M6: 0.26 | N6: Fail | O6: 8 | P6: Operations management, KPI leadership, CRM optimization, recruitment/training, QA, escalations and customer-service leadership. | Q6: No direct transportation, LIMO/chauffeur, dispatch-industry, affiliate/farm-out or US limo operations experience. | R6: Good service-operations leader but fails the position's core industry requirement. | S6: =IF($C6="","",IF(OR($M6="",$N6=""),'Lists & Settings'!$O$10,IF($N6="Fail",'Lists & Settings'!$O$9,IF($N6="Insufficient Evidence",'Lists & Settings'!$O$10,IF($N6="Pass",IF($M6>='Lists & Settings'!$N$2,'Lists & Settings'!$O$2,IF($M6>='Lists & Settings'!$N$3,'Lists & Settings'!$O$3,'Lists & Settings'!$O$4)),IF($N6="Partial",IF($M6>='Lists & Settings'!$N$6,'Lists & Settings'!$O$6,IF($M6>='Lists & Settings'!$N$7,'Lists & Settings'!$O$7,'Lists & Settings'!$O$8)),'Lists & Settings'!$O$10)))))) -> Reject | T6: Rejected | Y6: Qualitative Must-Have Fit: Fail. Latest strict Ref #001 decision: Reject. | AA6: 46291
A7: CAND-006 | B7: 001 | C7: Qaisar Khalid | D7: 0321-6517101 | E7: qasir.khalid08@gmail.com | F7: Warehouse & Logistic Operation Lead | G7: SWAT Agro Chemicals | H7: Faisalabad | K7: 46290 | L7: 7.5 | M7: 0.31 | N7: Fail | O7: 7 | P7: Logistics operations, staff supervision, budgets, vendors, warehousing and coordination with truck drivers/dispatchers. | Q7: Background is warehouse/supply-chain logistics, not US LIMO/chauffeur service management; no limo systems or affiliate network evidence. | R7: Transferable operations background only; direct client-required domain fit is weak. | S7: =IF($C7="","",IF(OR($M7="",$N7=""),'Lists & Settings'!$O$10,IF($N7="Fail",'Lists & Settings'!$O$9,IF($N7="Insufficient Evidence",'Lists & Settings'!$O$10,IF($N7="Pass",IF($M7>='Lists & Settings'!$N$2,'Lists & Settings'!$O$2,IF($M7>='Lists & Settings'!$N$3,'Lists & Settings'!$O$3,'Lists & Settings'!$O$4)),IF($N7="Partial",IF($M7>='Lists & Settings'!$N$6,'Lists & Settings'!$O$6,IF($M7>='Lists & Settings'!$N$7,'Lists & Settings'!$O$7,'Lists & Settings'!$O$8)),'Lists & Settings'!$O$10)))))) -> Reject | T7: Rejected | Y7: Original assessment: Not Preferred / Hold. Qualitative Must-Have Fit: Fail / Transferable. | AA7: 46291
A8: CAND-007 | B8: 001 | C8: Shahid Iqbal | D8: +92 345 4480810 / +92 315 9614787 | E8: shahed08@gmail.com | F8: Founder & Operations Manager | G8: Independent Retail & Production Unit | H8: Bahawalnagar | I8: 22 | K8: 46290 | L8: 5 | M8: 0.36 | N8: Fail | O8: 9 | P8: 22+ years operations leadership, P&L ownership, KPI setting, vendor/partner negotiation, multi-department coordination and team management. | Q8: Documented experience is manufacturing, supply chain and retail/production rather than LIMO/chauffeur operations or US customer service. | R8: Highly capable operations leader, but the CV does not prove the mandatory direct limo/chauffeur and US-market experience. | S8: =IF($C8="","",IF(OR($M8="",$N8=""),'Lists & Settings'!$O$10,IF($N8="Fail",'Lists & Settings'!$O$9,IF($N8="Insufficient Evidence",'Lists & Settings'!$O$10,IF($N8="Pass",IF($M8>='Lists & Settings'!$N$2,'Lists & Settings'!$O$2,IF($M8>='Lists & Settings'!$N$3,'Lists & Settings'!$O$3,'Lists & Settings'!$O$4)),IF($N8="Partial",IF($M8>='Lists & Settings'!$N$6,'Lists & Settings'!$O$6,IF($M8>='Lists & Settings'!$N$7,'Lists & Settings'!$O$7,'Lists & Settings'!$O$8)),'Lists & Settings'!$O$10)))))) -> Reject | T8: Rejected | Y8: Original assessment: Hold / Not Preferred. CV headline should not be treated as proof of ground-transport domain experience. | AA8: 46291
A9: CAND-008 | B9: 001 | C9: Ali Mahmood Qureshi | D9: +92 341 4333338 | E9: ali_mahmood22@hotmail.com | F9: Head of Customer Success | H9: Lahore | I9: 10 | K9: 46290 | L9: 8.5 | M9: 0.41 | N9: Fail | O9: 8.5 | P9: 10+ years global B2B customer success, US-market enterprise exposure, 50+ team leadership, SLA/KPI ownership, revenue growth and escalation management. | Q9: No direct chauffeur/limo operating experience, reservations, chauffeur dispatch, affiliate/farm-out network or limo systems. | R9: Strong US customer and service-delivery leadership but lacks the core LIMO/chauffeur operational requirement. | S9: =IF($C9="","",IF(OR($M9="",$N9=""),'Lists & Settings'!$O$10,IF($N9="Fail",'Lists & Settings'!$O$9,IF($N9="Insufficient Evidence",'Lists & Settings'!$O$10,IF($N9="Pass",IF($M9>='Lists & Settings'!$N$2,'Lists & Settings'!$O$2,IF($M9>='Lists & Settings'!$N$3,'Lists & Settings'!$O$3,'Lists & Settings'!$O$4)),IF($N9="Partial",IF($M9>='Lists & Settings'!$N$6,'Lists & Settings'!$O$6,IF($M9>='Lists & Settings'!$N$7,'Lists & Settings'!$O$7,'Lists & Settings'!$O$8)),'Lists & Settings'!$O$10)))))) -> Reject | T9: Rejected | Y9: Last documented employer: IP Global (role ended May 2026). Original assessment: Hold / Backup. | AA9: 46291
A10: CAND-009 | B10: 001 | C10: Hira Iqbal Ghaznavi | D10: 0321-4076912 | E10: hiraiqbal657@gmail.com | F10: Senior Sales Consultant | G10: 60 Minute Limo | I10: 8 | J10: 8 | K10: 46290 | L10: 9 | M10: 0.85 | N10: Partial | O10: 9.5 | P10: Direct premium chauffeured ground-transportation exposure; 8+ years across dispatch/logistics/operations; led 30+ dispatch/customer-support staff; KPI/reporting systems; vendor contracts; corporate-account operations; Limo Anywhere, Moovs, Santa Cruz, GNet and related dispatch platforms. | Q10: Explicit US-customer/US-market responsibility is still not evidenced in the CV. Full GM-level P&L ownership, affiliate rate/margin strategy, and oversight of marketing/SEO/development functions should also be validated. | R10: Strong Ref #001 fit with direct premium chauffeur-industry exposure, dispatch/logistics leadership, 30+ team management and extensive ground-transportation systems knowledge. Must-Have remains Partial only because explicit US-market exposure is not documented; interview validation is required. | S10: =IF($C10="","",IF(OR($M10="",$N10=""),'Lists & Settings'!$O$10,IF($N10="Fail",'Lists & Settings'!$O$9,IF($N10="Insufficient Evidence",'Lists & Settings'!$O$10,IF($N10="Pass",IF($M10>='Lists & Settings'!$N$2,'Lists & Settings'!$O$2,IF($M10>='Lists & Settings'!$N$3,'Lists & Settings'!$O$3,'Lists & Settings'!$O$4)),IF($N10="Partial",IF($M10>='Lists & Settings'!$N$6,'Lists & Settings'!$O$6,IF($M10>='Lists & Settings'!$N$7,'Lists & Settings'!$O$7,'Lists & Settings'!$O$8)),'Lists & Settings'!$O$10)))))) -> Shortlist | T10: Shortlisted | Y10: Assessment reconfirmed against uploaded CV on 2026-09-26. Existing ATS score and Shortlist decision retained; explicit US-market exposure remains the key validation point. | Z10: Hira Iqbal Ghaznavi.pdf | AA10: 46291
A11: CAND-010 | B11: 001 | C11: Ahmad Fraz | D11: +92 318 6088030 | E11: ahmadfraz090802@gmail.com | F11: Operations Associate | G11: EDKASA Pvt. Ltd. | H11: Lahore | I11: 5 | K11: 46290 | L11: 8 | M11: 0.37 | N11: Fail | O11: 7.5 | P11: Fleet dispatch, route optimization, driver incentives, vendor/maintenance coordination, KPI dashboards and team leadership. | Q11: Delivery/logistics fleet experience is transferable but not LIMO/chauffeur service management; no US limo customers, affiliate/farm-out or limo platforms. | R11: Solid logistics operator, but direct client-required limo/chauffeur and US-market evidence is missing. | S11: =IF($C11="","",IF(OR($M11="",$N11=""),'Lists & Settings'!$O$10,IF($N11="Fail",'Lists & Settings'!$O$9,IF($N11="Insufficient Evidence",'Lists & Settings'!$O$10,IF($N11="Pass",IF($M11>='Lists & Settings'!$N$2,'Lists & Settings'!$O$2,IF($M11>='Lists & Settings'!$N$3,'Lists & Settings'!$O$3,'Lists & Settings'!$O$4)),IF($N11="Partial",IF($M11>='Lists & Settings'!$N$6,'Lists & Settings'!$O$6,IF($M11>='Lists & Settings'!$N$7,'Lists & Settings'!$O$7,'Lists & Settings'!$O$8)),'Lists & Settings'!$O$10)))))) -> Reject | T11: Rejected | Y11: Original strict assessment: Hold / Not Preferred. Qualitative Must-Have Fit: Fail / Transferable. | AA11: 46291
A12: CAND-011 | B12: 001 | C12: Engr. Muhammad Arslan Ali | D12: +92-301-4387281 | E12: arslanalite20@gmail.com | F12: Logistics Manager (Logistics & Operations) | G12: Alfatah Shopping Mall - Warehouse Lahore | H12: Lahore | I12: 8 | J12: 8 | K12: 46290 | L12: 8.5 | M12: 0.39 | N12: Fail | O12: 8.5 | P12: 8+ years passenger transport/fleet operations, public transit, SLA/KPI management, outsourced operators, scheduling, vendor coordination and safety. | Q12: No commercial LIMO/chauffeur operations, US customer handling, affiliate/farm-out network, reservations or limo-specific platforms. | R12: Strong passenger-transport professional but not a direct match for the US LIMO/chauffeur service model. | S12: =IF($C12="","",IF(OR($M12="",$N12=""),'Lists & Settings'!$O$10,IF($N12="Fail",'Lists & Settings'!$O$9,IF($N12="Insufficient Evidence",'Lists & Settings'!$O$10,IF($N12="Pass",IF($M12>='Lists & Settings'!$N$2,'Lists & Settings'!$O$2,IF($M12>='Lists & Settings'!$N$3,'Lists & Settings'!$O$3,'Lists & Settings'!$O$4)),IF($N12="Partial",IF($M12>='Lists & Settings'!$N$6,'Lists & Settings'!$O$6,IF($M12>='Lists & Settings'!$N$7,'Lists & Settings'!$O$7,'Lists & Settings'!$O$8)),'Lists & Settings'!$O$10)))))) -> Reject | T12: Rejected | Y12: Re-evaluated under stricter Ref #001 criteria. Qualitative Must-Have Fit: Fail on core requirement. | AA12: 46291
A13: CAND-012 | B13: 001 | C13: Muhammad Ameer Hamza | D13: +92 3000987027 | E13: humzabutt419@yahoo.com | F13: Retired Captain | G13: Pakistan Army (Retired) | H13: Pakistan | I13: 8 | K13: 46290 | L13: 8 | M13: 0.27 | N13: Fail | O13: 8 | P13: Commissioned leadership, logistics, administration, crisis response, workforce planning and management of 700+ personnel. | Q13: No commercial LIMO/chauffeur operations, US customer handling, reservations/dispatch, affiliate/farm-out or limo software. | R13: Strong command and operations background, but not relevant enough to the client-specific chauffeur industry requirement. | S13: =IF($C13="","",IF(OR($M13="",$N13=""),'Lists & Settings'!$O$10,IF($N13="Fail",'Lists & Settings'!$O$9,IF($N13="Insufficient Evidence",'Lists & Settings'!$O$10,IF($N13="Pass",IF($M13>='Lists & Settings'!$N$2,'Lists & Settings'!$O$2,IF($M13>='Lists & Settings'!$N$3,'Lists & Settings'!$O$3,'Lists & Settings'!$O$4)),IF($N13="Partial",IF($M13>='Lists & Settings'!$N$6,'Lists & Settings'!$O$6,IF($M13>='Lists & Settings'!$N$7,'Lists & Settings'!$O$7,'Lists & Settings'!$O$8)),'Lists & Settings'!$O$10)))))) -> Reject | T13: Rejected | Y13: Qualitative Must-Have Fit: Fail. VIP movement experience was security-related, not commercial chauffeur service delivery. | AA13: 46291
A14: CAND-013 | B14: 001 | C14: Muhammad Khalid | D14: 923006231094 | E14: khalidrafiq0088@gmail.com | F14: Factory Manager | G14: Dura Flow Pvt. Ltd. | H14: Chishtian, Bahawalnagar | K14: 46290 | L14: 7.5 | M14: 0.21 | N14: Fail | O14: 7.5 | P14: General management, production planning, budgets, teams, cost control, quality and cross-functional manufacturing operations. | Q14: No LIMO/chauffeur service management, US customer operations, dispatch/reservations, affiliate/farm-out or limo systems. | R14: Credible general manager in manufacturing, but no alignment with the mandatory chauffeur/limo domain. | S14: =IF($C14="","",IF(OR($M14="",$N14=""),'Lists & Settings'!$O$10,IF($N14="Fail",'Lists & Settings'!$O$9,IF($N14="Insufficient Evidence",'Lists & Settings'!$O$10,IF($N14="Pass",IF($M14>='Lists & Settings'!$N$2,'Lists & Settings'!$O$2,IF($M14>='Lists & Settings'!$N$3,'Lists & Settings'!$O$3,'Lists & Settings'!$O$4)),IF($N14="Partial",IF($M14>='Lists & Settings'!$N$6,'Lists & Settings'!$O$6,IF($M14>='Lists & Settings'!$N$7,'Lists & Settings'!$O$7,'Lists & Settings'!$O$8)),'Lists & Settings'!$O$10)))))) -> Reject | T14: Rejected | Y14: Qualitative Must-Have Fit: Fail. Current role stated as Factory Manager. | AA14: 46291
A15: CAND-014 | B15: 001 | C15: Kumail Naqvi | D15: +92 312 044 1931 | E15: syedkaimy@gmail.com | F15: Business Development & Sales Operations Manager | I15: 10 | J15: 3.3 | K15: 46290 | L15: 8.5 | M15: 0.55 | N15: Fail | O15: 8 | P15: US-based freight dispatch experience in Houston; load booking, rate negotiation, driver scheduling, route planning, CRM/load boards and dispatcher supervision. | Q15: Experience is US freight/trucking logistics, not limousine/chauffeur service management; no limo reservations, premium passenger service, affiliate/farm-out or limo platforms. | R15: US dispatch exposure is useful and stronger than generic logistics, but the transportation vertical does not meet the core limo/chauffeur requirement. | S15: =IF($C15="","",IF(OR($M15="",$N15=""),'Lists & Settings'!$O$10,IF($N15="Fail",'Lists & Settings'!$O$9,IF($N15="Insufficient Evidence",'Lists & Settings'!$O$10,IF($N15="Pass",IF($M15>='Lists & Settings'!$N$2,'Lists & Settings'!$O$2,IF($M15>='Lists & Settings'!$N$3,'Lists & Settings'!$O$3,'Lists & Settings'!$O$4)),IF($N15="Partial",IF($M15>='Lists & Settings'!$N$6,'Lists & Settings'!$O$6,IF($M15>='Lists & Settings'!$N$7,'Lists & Settings'!$O$7,'Lists & Settings'!$O$8)),'Lists & Settings'!$O$10)))))) -> Reject | T15: Rejected | Y15: Last documented role: Head of Sales, Communications & Business Operations, LEXTON Logistics LLC (ended Jun 2026). | AA15: 46291
A16: CAND-015 | B16: 001 | C16: Rana Rashid Ali Sadiq | D16: 03207789165 | E16: rashidrana165@gmail.com | F16: Assistant Manager Workshop | G16: Veda Transit Solution (Metro Bus Service) | H16: Township, Lahore | J16: 7.3 | K16: 46291 | L16: 9 | M16: 0.34 | N16: Fail | O16: 7.5 | P16: Fleet/workshop leadership, route and transport management, maintenance strategy, driver performance, public transport and aviation fleet exposure. | Q16: No limousine/chauffeur service operations, US customers, reservations, affiliate/farm-out or limo platforms. | R16: Strong fleet and workshop profile but only transferable to the client-specific limo/chauffeur model. | S16: =IF($C16="","",IF(OR($M16="",$N16=""),'Lists & Settings'!$O$10,IF($N16="Fail",'Lists & Settings'!$O$9,IF($N16="Insufficient Evidence",'Lists & Settings'!$O$10,IF($N16="Pass",IF($M16>='Lists & Settings'!$N$2,'Lists & Settings'!$O$2,IF($M16>='Lists & Settings'!$N$3,'Lists & Settings'!$O$3,'Lists & Settings'!$O$4)),IF($N16="Partial",IF($M16>='Lists & Settings'!$N$6,'Lists & Settings'!$O$6,IF($M16>='Lists & Settings'!$N$7,'Lists & Settings'!$O$7,'Lists & Settings'!$O$8)),'Lists & Settings'!$O$10)))))) -> Reject | T16: Rejected | Y16: Original assessment: Hold / Not Preferred. Qualitative Must-Have Fit: Fail. | AA16: 46291
A17: CAND-016 | B17: 001 | C17: Iftikhar Ahmed | D17: +92 321 2886797 | E17: iftikharahmed0670@gmail.com | F17: Operations Excellence Manager | G17: Orange Line Metro Rail Transit System | H17: Lahore | I17: 23 | J17: 21 | K17: 46291 | L17: 9 | M17: 0.3 | N17: Fail | O17: 8 | P17: 23+ years operational excellence, metro passenger operations, fleet/workshop management, KPIs, vendors, audits, safety and continuous improvement. | Q17: No commercial LIMO/chauffeur operations, US customers, affiliate/farm-out, reservations or limo systems. | R17: Senior operations professional, but industry fit to US chauffeur/limo services is insufficient. | S17: =IF($C17="","",IF(OR($M17="",$N17=""),'Lists & Settings'!$O$10,IF($N17="Fail",'Lists & Settings'!$O$9,IF($N17="Insufficient Evidence",'Lists & Settings'!$O$10,IF($N17="Pass",IF($M17>='Lists & Settings'!$N$2,'Lists & Settings'!$O$2,IF($M17>='Lists & Settings'!$N$3,'Lists & Settings'!$O$3,'Lists & Settings'!$O$4)),IF($N17="Partial",IF($M17>='Lists & Settings'!$N$6,'Lists & Settings'!$O$6,IF($M17>='Lists & Settings'!$N$7,'Lists & Settings'!$O$7,'Lists & Settings'!$O$8)),'Lists & Settings'!$O$10)))))) -> Reject | T17: Rejected | Y17: Original assessment label: Not Preferred. Stored as Hold to preserve non-final rejection status. | AA17: 46291
A18: CAND-017 | B18: 001 | C18: Muhammad Kashif Iqbal | D18: +92 317 7184901 | E18: Kashif.iqbal5987@gmail.com | F18: Manager Operations | G18: Imperial Venture | H18: Gujranwala | J18: 1.8 | K18: 46291 | L18: 8.5 | M18: 0.18 | N18: Fail | O18: 5.5 | P18: Field operations, route management, driver productivity, SOPs, safety/HSE, reporting and waste-transport coordination. | Q18: No chauffeur/limo business, US customer operations, premium passenger service, affiliate/farm-out or limo dispatch systems. | R18: Operational exposure is in waste management/HSE and does not meet Ref #001 core domain requirements. | S18: =IF($C18="","",IF(OR($M18="",$N18=""),'Lists & Settings'!$O$10,IF($N18="Fail",'Lists & Settings'!$O$9,IF($N18="Insufficient Evidence",'Lists & Settings'!$O$10,IF($N18="Pass",IF($M18>='Lists & Settings'!$N$2,'Lists & Settings'!$O$2,IF($M18>='Lists & Settings'!$N$3,'Lists & Settings'!$O$3,'Lists & Settings'!$O$4)),IF($N18="Partial",IF($M18>='Lists & Settings'!$N$6,'Lists & Settings'!$O$6,IF($M18>='Lists & Settings'!$N$7,'Lists & Settings'!$O$7,'Lists & Settings'!$O$8)),'Lists & Settings'!$O$10)))))) -> Reject | T18: Rejected | Y18: Qualitative Must-Have Fit: Fail. | AA18: 46291
A19: CAND-018 | B19: 001 | C19: Nauman Atique | D19: +92 305 8215553 / +92 326 0590127 | E19: rananaumanatique@gmail.com | F19: DM Operations | G19: Sindh Solid Waste Management Board | Endurance Environment | H19: Lahore | I19: 10 | J19: 5.3 | K19: 46291 | L19: 9 | M19: 0.25 | N19: Fail | O19: 7.5 | P19: 10+ years operations/fleet management, route planning, vehicle deployment, vendor/contractor management, cost control and field-team leadership. | Q19: Experience is municipal/healthcare waste and environmental services; no LIMO/chauffeur or US-client operations. | R19: Strong fleet-management capability but the core industry requirement is absent. | S19: =IF($C19="","",IF(OR($M19="",$N19=""),'Lists & Settings'!$O$10,IF($N19="Fail",'Lists & Settings'!$O$9,IF($N19="Insufficient Evidence",'Lists & Settings'!$O$10,IF($N19="Pass",IF($M19>='Lists & Settings'!$N$2,'Lists & Settings'!$O$2,IF($M19>='Lists & Settings'!$N$3,'Lists & Settings'!$O$3,'Lists & Settings'!$O$4)),IF($N19="Partial",IF($M19>='Lists & Settings'!$N$6,'Lists & Settings'!$O$6,IF($M19>='Lists & Settings'!$N$7,'Lists & Settings'!$O$7,'Lists & Settings'!$O$8)),'Lists & Settings'!$O$10)))))) -> Reject | T19: Rejected | Y19: Qualitative Must-Have Fit: Fail. Direct chauffeur/limo evidence absent. | AA19: 46291
A20: CAND-019 | B20: 001 | C20: Razi Abbas | D20: +92-311-7365492 | E20: raziabbas7212@gmail.com | F20: Branch Manager | G20: Food Panda | H20: Multan | J20: 3 | K20: 46291 | L20: 8 | M20: 0.2 | N20: Fail | O20: 5.5 | P20: Branch operations, last-mile delivery, riders, hub dispatch, KPI tracking, inventory and service-quality management. | Q20: Comparatively junior and entirely e-commerce/food-delivery focused; no LIMO/chauffeur, US market or GM-level chauffeur operations. | R20: Useful last-mile exposure but far below the client-specific senior chauffeur/limo requirement. | S20: =IF($C20="","",IF(OR($M20="",$N20=""),'Lists & Settings'!$O$10,IF($N20="Fail",'Lists & Settings'!$O$9,IF($N20="Insufficient Evidence",'Lists & Settings'!$O$10,IF($N20="Pass",IF($M20>='Lists & Settings'!$N$2,'Lists & Settings'!$O$2,IF($M20>='Lists & Settings'!$N$3,'Lists & Settings'!$O$3,'Lists & Settings'!$O$4)),IF($N20="Partial",IF($M20>='Lists & Settings'!$N$6,'Lists & Settings'!$O$6,IF($M20>='Lists & Settings'!$N$7,'Lists & Settings'!$O$7,'Lists & Settings'!$O$8)),'Lists & Settings'!$O$10)))))) -> Reject | T20: Rejected | Y20: Qualitative Must-Have Fit: Fail. | AA20: 46291
A21: CAND-020 | B21: 001 | C21: Salman Khan Magsi | D21: 0300-4337261 | E21: salmanmagsi38@gmail.com | F21: Senior Manager Operations | G21: Secure Logistics Group | H21: Bahria Town, Lahore | I21: 23 | J21: 23 | K21: 46291 | L21: 9 | M21: 0.42 | N21: Fail | O21: 8.5 | P21: 23 years courier/logistics/transportation leadership; centralized dispatch, booking/forwarding, fleet outsourcing, multi-branch operations, costs and teams. | Q21: No limousine/chauffeur service management, US customer exposure, affiliate/farm-out limo network or limo-specific software. | R21: Strongest generic transport/logistics profile among recent batch, but still outside the mandatory US limo/chauffeur domain. | S21: =IF($C21="","",IF(OR($M21="",$N21=""),'Lists & Settings'!$O$10,IF($N21="Fail",'Lists & Settings'!$O$9,IF($N21="Insufficient Evidence",'Lists & Settings'!$O$10,IF($N21="Pass",IF($M21>='Lists & Settings'!$N$2,'Lists & Settings'!$O$2,IF($M21>='Lists & Settings'!$N$3,'Lists & Settings'!$O$3,'Lists & Settings'!$O$4)),IF($N21="Partial",IF($M21>='Lists & Settings'!$N$6,'Lists & Settings'!$O$6,IF($M21>='Lists & Settings'!$N$7,'Lists & Settings'!$O$7,'Lists & Settings'!$O$8)),'Lists & Settings'!$O$10)))))) -> Reject | T21: Rejected | Y21: Original assessment: Hold / Backup Only. Qualitative Must-Have Fit: Fail / Transferable. | AA21: 46291
A22: CAND-021 | B22: 001 | C22: Raza Shahzad | D22: +92-3214007507 | E22: razashahzad52@gmail.com | K22: 46291 | L22: 7.5 | M22: 0.34 | N22: Fail | O22: 7.5 | P22: Operations management, vendors/contractors, target setting, multi-region team supervision, CRM and service-provider coordination. | Q22: No limousine/chauffeur operations, US customer handling, dispatch/reservations, affiliate/farm-out or limo platforms. | R22: General operations experience is relevant only at a transferable level and does not satisfy the core requirement. | S22: =IF($C22="","",IF(OR($M22="",$N22=""),'Lists & Settings'!$O$10,IF($N22="Fail",'Lists & Settings'!$O$9,IF($N22="Insufficient Evidence",'Lists & Settings'!$O$10,IF($N22="Pass",IF($M22>='Lists & Settings'!$N$2,'Lists & Settings'!$O$2,IF($M22>='Lists & Settings'!$N$3,'Lists & Settings'!$O$3,'Lists & Settings'!$O$4)),IF($N22="Partial",IF($M22>='Lists & Settings'!$N$6,'Lists & Settings'!$O$6,IF($M22>='Lists & Settings'!$N$7,'Lists & Settings'!$O$7,'Lists & Settings'!$O$8)),'Lists & Settings'!$O$10)))))) -> Reject | T22: Rejected | Y22: Last documented role: Operations Manager, High Tide Inc (ended Mar 2026). Qualitative Must-Have Fit: Fail. | AA22: 46291
A23: CAND-022 | B23: 001 | C23: Alam Fazal | D23: +92-321-9886773 | E23: alam.fazal@yahoo.com | F23: Incharge Fleet Operations, Maintenance & Logistics | G23: Daewoo Express Bus Service Pakistan | H23: Bahria Orchard, Lahore | J23: 13 | K23: 46291 | L23: 9 | M23: 0.39 | N23: Fail | O23: 8.5 | P23: Passenger-transport fleet operations, depot leadership, 90+ staff supervision, vendors, KPIs, maintenance budgets and cross-functional coordination. | Q23: No LIMO/chauffeur service management, US-based customers, reservations/booking, affiliate/farm-out or limo-specific software. | R23: Credible passenger-transport operator but direct US chauffeur/limo domain fit is unproven. | S23: =IF($C23="","",IF(OR($M23="",$N23=""),'Lists & Settings'!$O$10,IF($N23="Fail",'Lists & Settings'!$O$9,IF($N23="Insufficient Evidence",'Lists & Settings'!$O$10,IF($N23="Pass",IF($M23>='Lists & Settings'!$N$2,'Lists & Settings'!$O$2,IF($M23>='Lists & Settings'!$N$3,'Lists & Settings'!$O$3,'Lists & Settings'!$O$4)),IF($N23="Partial",IF($M23>='Lists & Settings'!$N$6,'Lists & Settings'!$O$6,IF($M23>='Lists & Settings'!$N$7,'Lists & Settings'!$O$7,'Lists & Settings'!$O$8)),'Lists & Settings'!$O$10)))))) -> Reject | T23: Rejected | Y23: Original assessment: Hold / Not Preferred. Qualitative Must-Have Fit: Fail / Transferable. | AA23: 46291
A24: CAND-023 | B24: 001 | C24: Rizwan Khan Bangash | D24: +92 300 6665444 | E24: rizwan6665444@gmail.com | F24: Centralized Warehouse & Inventory Control Manager | G24: AGI Denim | H24: Karachi | I24: 20 | K24: 46291 | L24: 9 | M24: 0.24 | N24: Fail | O24: 7.5 | P24: 20+ years supply-chain, warehouse, inventory, production planning, lean process improvement and global buyer coordination. | Q24: No passenger transportation, LIMO/chauffeur operations, US limo customers, reservations/dispatch, affiliate/farm-out or limo systems. | R24: Strong supply-chain leader but no relevant chauffeur-industry experience for Ref #001. | S24: =IF($C24="","",IF(OR($M24="",$N24=""),'Lists & Settings'!$O$10,IF($N24="Fail",'Lists & Settings'!$O$9,IF($N24="Insufficient Evidence",'Lists & Settings'!$O$10,IF($N24="Pass",IF($M24>='Lists & Settings'!$N$2,'Lists & Settings'!$O$2,IF($M24>='Lists & Settings'!$N$3,'Lists & Settings'!$O$3,'Lists & Settings'!$O$4)),IF($N24="Partial",IF($M24>='Lists & Settings'!$N$6,'Lists & Settings'!$O$6,IF($M24>='Lists & Settings'!$N$7,'Lists & Settings'!$O$7,'Lists & Settings'!$O$8)),'Lists & Settings'!$O$10)))))) -> Reject | T24: Rejected | Y24: Qualitative Must-Have Fit: Fail. | AA24: 46291
A25: CAND-024 | B25: 001 | C25: Waqas Ali | D25: +92 306 7307079 | E25: waqasalisidhu06@gmail.com | F25: Deputy Manager Operations | G25: Faisal Movers Express – Orange Line Metro Bus Project | H25: Bahawalpur | I25: 10 | J25: 10 | K25: 46291 | L25: 8.5 | M25: 0.44 | N25: Fail | O25: 8.5 | P25: 10+ years public passenger transport, dispatch management, fleet scheduling, ITS, route optimization, crisis response and very large workforce management. | Q25: Experience is public bus/transit operations with no documented LIMO/chauffeur business, US customers, affiliate/farm-out, reservations or limo platforms. | R25: Operationally strong transport candidate but only a backup because direct US limo/chauffeur experience is absent. | S25: =IF($C25="","",IF(OR($M25="",$N25=""),'Lists & Settings'!$O$10,IF($N25="Fail",'Lists & Settings'!$O$9,IF($N25="Insufficient Evidence",'Lists & Settings'!$O$10,IF($N25="Pass",IF($M25>='Lists & Settings'!$N$2,'Lists & Settings'!$O$2,IF($M25>='Lists & Settings'!$N$3,'Lists & Settings'!$O$3,'Lists & Settings'!$O$4)),IF($N25="Partial",IF($M25>='Lists & Settings'!$N$6,'Lists & Settings'!$O$6,IF($M25>='Lists & Settings'!$N$7,'Lists & Settings'!$O$7,'Lists & Settings'!$O$8)),'Lists & Settings'!$O$10)))))) -> Reject | T25: Rejected | Y25: Original assessment: Hold / Backup Only. Qualitative Must-Have Fit: Fail / Transferable. | AA25: 46291
A26: CAND-025 | B26: 001 | C26: M. Sohail Shahid | D26: +966 554513158 / +92 307 6261861 | E26: msohailshahid79@gmail.com | F26: Electronics Engineer | G26: Prince Sultan Military Medical City via Binjarallah Group | H26: Riyadh, Saudi Arabia | J26: 5 | K26: 46291 | L26: 9 | M26: 0.33 | N26: Fail | O26: 7 | P26: Five years metro transportation operations, staff/shift supervision, control-room coordination, passenger service, incident response and technical systems. | Q26: No commercial LIMO/chauffeur operations, US customers, reservations, affiliate/farm-out or limo-specific software; current role is technical engineering. | R26: Relevant public-transit operations but not aligned with the commercial US chauffeur/limo service model. | S26: =IF($C26="","",IF(OR($M26="",$N26=""),'Lists & Settings'!$O$10,IF($N26="Fail",'Lists & Settings'!$O$9,IF($N26="Insufficient Evidence",'Lists & Settings'!$O$10,IF($N26="Pass",IF($M26>='Lists & Settings'!$N$2,'Lists & Settings'!$O$2,IF($M26>='Lists & Settings'!$N$3,'Lists & Settings'!$O$3,'Lists & Settings'!$O$4)),IF($N26="Partial",IF($M26>='Lists & Settings'!$N$6,'Lists & Settings'!$O$6,IF($M26>='Lists & Settings'!$N$7,'Lists & Settings'!$O$7,'Lists & Settings'!$O$8)),'Lists & Settings'!$O$10)))))) -> Reject | T26: Rejected | Y26: Qualitative Must-Have Fit: Fail. Relevant Experience field reflects explicitly stated 5 years in transportation operations. | AA26: 46291
A27: CAND-026 | B27: 001 | C27: Inam Ur Rehman | D27: 0307-0150150 | E27: inamu9581@gmail.com | F27: Supply Chain Executive (Logistics) | G27: Gourmet Foods Pakistan (Head Office) | H27: Lahore | I27: 8.6 | J27: 3 | K27: 46291 | L27: 8.5 | M27: 0.27 | N27: Fail | O27: 6.5 | P27: FMCG logistics and dispatch operations; vehicle allocation, route scheduling, shipment monitoring, 3PL/transporter coordination, warehouse operations, KPI reporting, SAP/WMS exposure. | Q27: No direct LIMO/chauffeur service management, no US-customer/market exposure, no premium passenger reservations/affiliate farm-out model, and no limo-specific software. | R27: Strong transferable logistics/dispatch profile, but both Ref #001 knockout requirements are absent and current seniority is below GM-level chauffeur operations. | S27: =IF($C27="","",IF(OR($M27="",$N27=""),'Lists & Settings'!$O$10,IF($N27="Fail",'Lists & Settings'!$O$9,IF($N27="Insufficient Evidence",'Lists & Settings'!$O$10,IF($N27="Pass",IF($M27>='Lists & Settings'!$N$2,'Lists & Settings'!$O$2,IF($M27>='Lists & Settings'!$N$3,'Lists & Settings'!$O$3,'Lists & Settings'!$O$4)),IF($N27="Partial",IF($M27>='Lists & Settings'!$N$6,'Lists & Settings'!$O$6,IF($M27>='Lists & Settings'!$N$7,'Lists & Settings'!$O$7,'Lists & Settings'!$O$8)),'Lists & Settings'!$O$10)))))) -> Reject | T27: Rejected | Y27: Direct LIMO/chauffeur and US-market must-haves are not evidenced. Relevant Industry Experience reflects logistics/dispatch/warehouse operations from Oct 2023 to present; older KPO/NSER roles are not counted as relevant industry experience. | AA27: 46291
A28: CAND-027 | B28: 001 | C28: Habab Bin Ayyaz | D28: +92 (323) 471-7225 | E28: hababbinayyaz@gmail.com | F28: Assistant Operations Manager | G28: Elite Chauffeured Service Inc. | H28: Lahore, Pakistan | I28: 4 | J28: 4 | K28: 46291 | L28: 9.5 | M28: 0.9 | N28: Pass | O28: 8.5 | P28: Direct US chauffeur/limo operations; current Assistant Operations Manager; prior Lead Dispatcher; trip assignment and execution; corporate accounts, travel agencies, DMCs, hotels and affiliate networks; Limo Anywhere, Moovs, GNet and Crewslink. | Q28: Leadership scope, team size, hiring/coaching responsibility, P&L ownership, affiliate rate/margin strategy, and oversight of marketing/SEO/development teams are not evidenced in the CV. | R28: High-alignment candidate with direct US limousine/chauffeur operations across Washington D.C. and New York, plus Canada dispatch exposure. Strong dispatch, affiliate-network and limo-platform evidence; broader GM-level commercial and people leadership should be validated. | S28: =IF($C28="","",IF(OR($M28="",$N28=""),'Lists & Settings'!$O$10,IF($N28="Fail",'Lists & Settings'!$O$9,IF($N28="Insufficient Evidence",'Lists & Settings'!$O$10,IF($N28="Pass",IF($M28>='Lists & Settings'!$N$2,'Lists & Settings'!$O$2,IF($M28>='Lists & Settings'!$N$3,'Lists & Settings'!$O$3,'Lists & Settings'!$O$4)),IF($N28="Partial",IF($M28>='Lists & Settings'!$N$6,'Lists & Settings'!$O$6,IF($M28>='Lists & Settings'!$N$7,'Lists & Settings'!$O$7,'Lists & Settings'!$O$8)),'Lists & Settings'!$O$10)))))) -> Priority Shortlist | T28: Shortlisted | Y28: Must-Have Fit = Pass. Approximately four years of direct luxury ground-transportation experience from 2022 to present, including US chauffeur operations and lead/assistant-management responsibilities. | AA28: 46291
A29: CAND-028 | B29: 002 | C29: Jaffir Iqbal | D29: +92302-9113015 | E29: jaffiriqbal@gmail.com | F29: Assistant Manager Production | G29: Cakes & Bakes Private Limited | H29: Tehsil Kabirwala, District Khanewal, Pakistan | I29: 9 | J29: 9 | K29: 46292 | L29: 8.8 | M29: 0.76 | N29: Pass | O29: 6.2 | P29: Multi-category food, sweets and bakery manufacturing experience: Directly supervised production of biscuits, croissants/cross products, plain cakes, jams, sauces, chocolate and frozen items at Cakes & Bakes. The employer is described as manufacturing snacks, bakery products, chocolate, chips, jam, ketchup and drinks. Additional food-sector experience includes PepsiCo and Bunny’s Limited. Relevant bachelor's degree: Completed BS in Food Science and Technology from Government College University Faisalabad, 2012–2016, with a 3.58/4.0 GPA. Also completed an M.Sc. (Honors) in Food Technology from the University of Agriculture Faisalabad. Minimum five years of production management experience: Assistant Manager Production at Cakes & Bakes from February 2019 to present. Responsibilities include maintaining production flow, meeting production plans, managing overall operations, delivering production targets, supervising multiple product processes, training workers and resolving production problems. | Q29: Dispatch, finished-goods inventory and expiry management: There is transferable inventory and order-fulfillment exposure, but direct responsibility for dispatch accuracy, customer deliveries, finished-goods warehousing, FEFO, shelf-life controls, near-expiry monitoring or returns is not evidenced. | R29: Candidate assessed against 9 live ATS criteria. Weighted ATS Match: 76%. Must-Have Fit: Pass. The result is based on the stored Ref # criteria, weights, knockout rules and documented CV evidence. | S29: Priority Shortlist | T29: Shortlisted | AA29: 46292.096
A30: CAND-029 | B30: 003 | C30: Jawad Ahmed | D30: +92 314-8002002 | E30: jawad4157@yahoo.com | F30: Manager – Export Sales and Marketing | G30: International Steels Limited | H30: Karachi, Sindh, Pakistan | I30: 16.6 | J30: 2 | K30: 46292 | L30: 9.3 | M30: 0.55 | N30: Fail | O30: 7.2 | P30: International market development and export strategy: Developed export strategies for Afghanistan, Sri Lanka, UAE, Oman, Qatar, Jordan and Australia; subsequently assumed responsibility for Saudi Arabia, Kuwait and regions across Africa. Conducted market research, secured entry into Saudi Arabia and Kuwait, facilitated SRIM certification for regulated-market access, converted more than 40 active leads into prospects, increased export revenue from USD 34 million to USD 41 million, and raised export contribution from 8% to 20%. Represented the company at international exhibitions, trade missions and business forums. Commercial negotiations, budgeting and international trade risk: Leads annual export budgeting, revenue forecasting and cost optimization against profit targets. Negotiates contracts, pricing models and payment structures, manages high-value accounts and reports export revenue growth from USD 34 million to USD 41 million. International client, distributor and service-provider relationship management: Manages international B2B and B2C key accounts, develops high-value client relationships, negotiates long-term agreements and reports strong retention and satisfaction. Works across multiple Asian, Middle Eastern, Australian and African markets and generated more than 40 active leads. | Q30: Export management experience and end-to-end ownership: The candidate demonstrates substantial commercial ownership and cross-functional coordination for international orders, but the CV evidences only two completed years of direct export management through July 2025, below the mandatory five-year threshold. It also does not explicitly demonstrate hands-on ownership of documentation, customs clearance, shipment and final delivery. Confectionery and perishable food export domain knowledge: The CV provides no usable evidence of confectionery or comparable perishable-food export knowledge. Steel export experience cannot be treated as direct food-domain experience. Trade compliance, food safety and export documentation: There is credible regulatory and certification exposure, but limited evidence of hands-on export-documentation or customs responsibility. No food-safety, food-labeling or destination-country food compliance experience is evidenced. | R30: Candidate assessed against 8 live ATS criteria. Weighted ATS Match: 55%. Must-Have Fit: Fail. The result is based on the stored Ref # criteria, weights, knockout rules and documented CV evidence. | S30: Reject | T30: Rejected | AA30: 46292.282
A31: CAND-030 | B31: 001 | C31: Muhammad Taskeen | D31: +92 300 6676139 / +92 333 6676139 | E31: muhammadtaskeen@gmai.com / muhammadtaskeen@outlool.com | F31: Security Supervisor | G31: Marine Security Service (Pvt) | H31: Faisalabad, Pakistan | I31: 27.4 | J31: 22.9 | K31: 46292 | L31: 8.9 | M31: 0.34 | N31: Fail | O31: 5.6 | P31: Dispatch / Fleet Operations: Managed daily vehicle movement, fleet availability, driver coordination and duty rosters, maintenance scheduling, fuel and mileage records, vehicle inspections, breakdowns, and transport-related incidents. Operations Management: Supervised daily transport operations, fleet availability, inspections, preventive maintenance, fuel consumption, vehicle records, incident investigations, roadworthiness, spare parts, and operational briefings in the Pakistan Air Force. Leadership & People Management: Served as a Warrant Officer and Mechanical Transport Supervisor; coordinated drivers, monitored attendance and duty rosters, conducted safety briefings and driver training, and completed leadership, command, and MT instructor courses. | Q31: Direct LIMO / Chauffeur Service Management: The VIP driving course and transport background are adjacent, but training and generic fleet management are not equivalent to directly managing a commercial limo or chauffeur operation. The mandatory direct-industry requirement is not met. US Market / US Customer Exposure: The CV only documents employment in Pakistan and provides no explicit international or US-facing operational experience. The mandatory US exposure requirement is not met. Client / Customer Management: Communication and interpersonal skills are listed, but there is no usable evidence of responsibility for customers or client accounts. | R31: Candidate assessed against 7 live ATS criteria. Weighted ATS Match: 34%. Must-Have Fit: Fail. The result is based on the stored Ref # criteria, weights, knockout rules and documented CV evidence. | S31: Reject | T31: Rejected | AA31: 46292.494
A32: CAND-031 | B32: 002 | C32: Husnain Raza Rahat | D32: 0304-0743974 | E32: husnainhadi899@gmail.com | F32: Assistant Manager (Production & Quality) | G32: Merit | H32: Mongi Bangla, Tehsil Gojra, District Toba Tek Singh, Pakistan | I32: 4 | J32: 4 | K32: 46293 | L32: 8.4 | M32: 0.59 | N32: Partial | O32: 5.5 | P32: Relevant bachelor's degree: BS (Hons) Food Science and Technology, Government College University Faisalabad, 2014–2018. Multi-category food, sweets and bakery manufacturing experience: Direct responsibility for multiple production lines covering bread, burgers, buns, rusk and other bakery products. Previous roles include Shift Incharge (Production) at Dawn Bread and Executive (Quality Assurance & Food Safety) in a food business. Skills include testing flour, milk, butter, oil, desi ghee and khoya, finished-goods testing and shelf-life studies. Quality control and health and safety compliance: Current responsibilities include daily and monthly quality and food-safety audits, daily quality-report review, regulatory-standard implementation, GMP and food-safety training, Halal Food Management System, IPM protocol, finished-product checks, preventive actions and complaints handling. Earlier role was Executive (Quality Assurance & Food Safety), 2018–2021. | Q32: Minimum five years of production management experience: The CV demonstrates direct factory-production responsibility, but it does not substantiate at least five years of production management. Only approximately one explicitly dated year is in a production leadership role, while the duration of the current assistant-manager position is not provided. Dispatch, finished-goods inventory and expiry management: The shelf-life and finished-product exposure is adjacent to the requirement, but direct dispatch and expiry-sensitive inventory ownership is not evidenced. Production systems, analytical reporting and decision support: A relevant ERP platform and routine reporting exposure are identified, but the CV does not explain hands-on SAP use for production planning, manufacturing transactions, analysis, MIS preparation or management decision support. | R32: Candidate assessed against 9 live ATS criteria. Weighted ATS Match: 59%. Must-Have Fit: Partial. The result is based on the stored Ref # criteria, weights, knockout rules and documented CV evidence. | S32: Hold | T32: Hold | AA32: 46292.969
A33: CAND-032 | B33: 004 | C33: Zeeshan Tarar | D33: 0345-4914004 | E33: zeeshan_tarar36@yahoo.com | F33: Assistant Manager Procurement | G33: Ajmair Foods | I33: 10 | J33: 6.3 | K33: 46296 | L33: 8.4 | M33: 0.52 | N33: Fail | O33: 6.2 | P33: Supplier sourcing, relationship management and market intelligence: Responsibilities include identifying, evaluating and managing suppliers; maintaining supplier relationships; resolving supplier issues; analyzing supplier performance, market trends and costs; competitive sourcing; and maintaining supplier data. At Thal/Almoiz, the candidate built supplier relationships and reported on supplier performance. Commercial negotiation, contracting and cost optimization: The CV describes negotiating supplier contracts, pricing, delivery terms, quality standards and payment terms; drafting, reviewing and managing contracts; securing favorable terms; developing cost-effective procurement strategies; and contributing to cost-saving initiatives. Procurement systems, reporting and audit-ready records: The candidate managed purchase-order creation, processing and tracking; prepared monthly and annual procurement reports; analyzed costs, volumes and supplier performance; maintained purchase and supplier records; used procurement software and tools; and completed ERP training. | Q33: Minimum experience and manufacturing-domain relevance: The candidate has substantial procurement and food/raw-material exposure, including more than six completed years in fruit procurement at a food company. However, the mandatory five years of production management are not evidenced, so the experience is relevant but does not satisfy the requirement as written. Inventory planning, replenishment and logistics coordination: Delivery and logistics coordination are directly evidenced, but the CV does not show responsibility for stock-level monitoring, reorder points, replenishment planning, shortage prevention or overstock control. Mandatory supply chain education: The CV does not evidence the specifically mandated bachelor's degree in Supply Chain Management. Procurement experience, ERP training and other short courses cannot substitute for the required degree. | R33: Candidate assessed against 8 live ATS criteria. Weighted ATS Match: 52%. Must-Have Fit: Fail. The result is based on the stored Ref # criteria, weights, knockout rules and documented CV evidence. | S33: Reject | T33: Rejected | Z33: https://drive.google.com/file/d/1kZbWCNdECoiACxOlAyOQNhp19dExclI2/view?usp=drivesdk | AA33: 46296.187
A34: CAND-033 | B34: 004 | C34: Abdul Ghaffar | D34: +92 305 4942108 | E34: agmohsinbutt5cwak_5hk@indeedemail.com | F34: Sr. Executive Supply Chain | G34: Quick Food Industries Pvt. Ltd. (MonSalwa) | H34: Lahore | I34: 15.1 | J34: 15.1 | K34: 46296 | L34: 8.1 | M34: 0.35 | N34: Fail | O34: 3.9 | P34: Cross-functional leadership and procurement decision-making: Describes handling all plant purchasing single-handedly, acting as supply-chain and procurement department in-charge, serving as a key person for production and maintenance, and coordinating with distribution, cold store and administration. Supplier sourcing, relationship management and market intelligence: States direct access to manufacturers and importers, knowledge of Lahore and Faisalabad markets, sourcing links to Karachi, direct-source purchasing of construction materials, and responsibility for supplier accounts and payment settlements. | Q34: Minimum experience and manufacturing-domain relevance: The candidate has extensive procurement experience in food and manufacturing environments, but the mandatory five years of production management experience is not evidenced. Coordination with production is transferable but is not production management. Commercial negotiation, contracting and cost optimization: The CV shows exposure to commercial transactions and payment arrangements but does not explicitly evidence price negotiation, contract ownership, bulk-purchase terms, cost analysis or quantified savings. Inventory planning, replenishment and logistics coordination: Logistics and cross-functional material coordination are evident, but stock monitoring, reorder-point management, shortage prevention, overstock control and supplier-delivery performance ownership are not specifically described. | R34: Candidate assessed against 8 live ATS criteria. Weighted ATS Match: 35%. Must-Have Fit: Fail. The result is based on the stored Ref # criteria, weights, knockout rules and documented CV evidence. | S34: Reject | T34: Rejected | Z34: https://drive.google.com/file/d/1dJQh0JBWSXzS5N9Hc8INE8K3LRJEgIpa/view?usp=drivesdk | AA34: 46296.187
A35: CAND-034 | B35: 004 | C35: Muhammad Zohaib Manzoor | D35: 0321-6883884 | E35: mzohaib330@yahoo.com | F35: Assistant Manager | G35: Cakes and Bakes (Ajmair Foods Pvt. Limited) | H35: Lahore, Pakistan | I35: 16.7 | J35: 6.6 | K35: 46294 | L35: 7.7 | M35: 0.49 | N35: Fail | O35: 5.8 | P35: Supplier sourcing, relationship management and market intelligence: Current responsibilities explicitly include supplier relationship management, researching and evaluating prospective suppliers, identifying potential new suppliers, supplier follow-up and introducing new products and services. At Millat Tractors, responsibilities included collecting quotations and negotiating with suppliers. Commercial negotiation, contracting and cost optimization: The CV explicitly lists supplier negotiation at Cakes and Bakes and collection of quotations and negotiations at Millat Tractors. It also notes comparative-statement preparation, price committee meetings and issuance of cash and credit purchase orders. Procurement systems, reporting and audit-ready records: The candidate issued purchase orders and created new purchase part numbers in IFS at Millat Tractors. Other documented system use includes IFS for production records, work orders, shop orders and inspection-related transactions. Reporting experience includes stock, production, maintenance and project reports, comparative statements, approval letters and CEP documentation. Microsoft Office and MS Project are also listed. | Q35: Minimum experience and manufacturing-domain relevance: The candidate has substantial procurement experience and direct bakery/food-production exposure, plus earlier manufacturing experience. This is relevant but does not meet the JD's explicit requirement for at least five years of production management. Inventory planning, replenishment and logistics coordination: There is credible delivery and material coordination experience, but no clear ownership of stock-level monitoring, reorder points, replenishment planning, shortage prevention or overstock controls. Mandatory supply chain education: The mandatory requirement specifically calls for a completed bachelor's degree in Supply Chain Management. The short course and procurement experience do not satisfy the stated degree-level and field requirement. | R35: Candidate assessed against 8 live ATS criteria. Weighted ATS Match: 49%. Must-Have Fit: Fail. The result is based on the stored Ref # criteria, weights, knockout rules and documented CV evidence. | S35: Reject | T35: Rejected | AA35: 46293.959
